{"name": "CONSULTA EN BD", "status": "broken", "statusDetails": {"message": "AttributeError: 'VariousFunctions' object has no attribute 'conn_ps'\n", "trace": "  File \"c:\\users\\jose.carpintero\\anaconda3\\lib\\site-packages\\behave\\model.py\", line 1329, in run\n    match.run(runner.context)\n  File \"c:\\users\\jose.carpintero\\anaconda3\\lib\\site-packages\\behave\\matchers.py\", line 98, in run\n    self.func(context, *args, **kwargs)\n  File \"features\\steps\\steps.py\", line 102, in step_impl\n    context.variuos_functions.conn_ps()\n"}, "steps": [{"name": "Given El usuario navega a la p√°gina principal", "status": "passed", "attachments": [{"source": "82f3bfd2-ceb0-46de-81d4-194532d0ae34-attachment.png", "type": "image/png"}], "start": 1595860413183, "stop": 1595860414121}, {"name": "When El usuario consulta en bd", "status": "broken", "statusDetails": {"message": "AttributeError: 'VariousFunctions' object has no attribute 'conn_ps'\n", "trace": "  File \"c:\\users\\jose.carpintero\\anaconda3\\lib\\site-packages\\behave\\model.py\", line 1329, in run\n    match.run(runner.context)\n  File \"c:\\users\\jose.carpintero\\anaconda3\\lib\\site-packages\\behave\\matchers.py\", line 98, in run\n    self.func(context, *args, **kwargs)\n  File \"features\\steps\\steps.py\", line 102, in step_impl\n    context.variuos_functions.conn_ps()\n"}, "start": 1595860414122, "stop": 1595860414124}], "start": 1595860413181, "stop": 1595860414124, "uuid": "83fb83c9-0354-4e59-99f5-d2d2c812e035", "historyId": "f5fb7a251dbb7b6a6fc4e5a7500d56b3", "labels": [{"name": "severity", "value": "normal"}, {"name": "tag", "value": "primeread-1"}, {"name": "feature", "value": "Pruebas PR."}, {"name": "framework", "value": "behave"}, {"name": "language", "value": "cpython3"}]}