{"name": "CONSULTA EN BD", "status": "broken", "statusDetails": {"message": "AttributeError: 'VariousFunctions' object has no attribute 'conn_ps'\n", "trace": "  File \"c:\\users\\jose.carpintero\\anaconda3\\lib\\site-packages\\behave\\model.py\", line 1329, in run\n    match.run(runner.context)\n  File \"c:\\users\\jose.carpintero\\anaconda3\\lib\\site-packages\\behave\\matchers.py\", line 98, in run\n    self.func(context, *args, **kwargs)\n  File \"features\\steps\\steps.py\", line 102, in step_impl\n    context.variuos_functions.conn_ps()\n"}, "steps": [{"name": "Given El usuario navega a la p√°gina principal", "status": "passed", "attachments": [{"source": "fb3d940c-9d8e-4cf1-b5cd-db0df83d43de-attachment.png", "type": "image/png"}], "start": 1595860766288, "stop": 1595860767330}, {"name": "When El usuario consulta en bd", "status": "broken", "statusDetails": {"message": "AttributeError: 'VariousFunctions' object has no attribute 'conn_ps'\n", "trace": "  File \"c:\\users\\jose.carpintero\\anaconda3\\lib\\site-packages\\behave\\model.py\", line 1329, in run\n    match.run(runner.context)\n  File \"c:\\users\\jose.carpintero\\anaconda3\\lib\\site-packages\\behave\\matchers.py\", line 98, in run\n    self.func(context, *args, **kwargs)\n  File \"features\\steps\\steps.py\", line 102, in step_impl\n    context.variuos_functions.conn_ps()\n"}, "start": 1595860767331, "stop": 1595860767331}], "start": 1595860766287, "stop": 1595860767332, "uuid": "f8f22071-bd64-40f3-91c7-b76eacbb20b5", "historyId": "f5fb7a251dbb7b6a6fc4e5a7500d56b3", "labels": [{"name": "severity", "value": "normal"}, {"name": "tag", "value": "primeread-1"}, {"name": "feature", "value": "Pruebas PR."}, {"name": "framework", "value": "behave"}, {"name": "language", "value": "cpython3"}]}